<?xml version='1.0'?>

<robot name="bob" xmlns:xacro="http://www.ros.org/wiki/xacro">
	<xacro:property name="robot_name" value="bob" />
	<xacro:property name="robot_chassis_mass" value="15"/>
	<xacro:property name="robot_chassis_length" value="0.2"/>
	<!-- <xacro:property name="robot_chassis_radius" value="0.25"/> -->
	<!-- <xacro:property name="robot_caster_wheel_radius" value="0.05"/> -->
	<!-- <xacro:property name="robot_caster_wheel_radius_collision" value="0.0499"/> -->

	<xacro:property name="robot_wheel_mass" value="5"/>
	<xacro:property name="robot_wheel_length" value="0.05"/>
	<xacro:property name="robot_wheel_radius" value="0.1"/>

	<!-- for realsense -->
	<xacro:property name="camera_mass" value="0.1"/>


	<!-- Make Chassis of Bot -->
	<link name="chassis">
		<pose>0 0 0.1 0 0 0</pose>

		<inertial>
			<mass value="${robot_chassis_mass}"/>
      		<origin xyz="0.0 0 0" rpy=" 0 0 0"/>

      		<inertia 
      			ixx="0.147116667" ixy="0" ixz="0"
      			iyy="0.334951167" iyz="0"
      			izz="0.3978345"
      		/>
		</inertial>

		<collision name="collision">
			<origin xyz="0 0 0.05" rpy=" 0 0 0"/>
			<geometry>
				<box size="0.5 0.5 0.2"/>
			</geometry>
		</collision>

		<visual name="chassis_visual">
			<origin xyz="0 0 0.05" rpy=" 0 0 0"/>
			<geometry>
				<box size="0.5 0.5 0.2"/>
			</geometry>
		</visual>
	</link>


	<!-- <xacro:include filename="$(find realsense_ros_gazebo)/xacro/depthcam.xacro"/>

	<xacro:realsense_d435 sensor_name="d435" parent_link="chassis" rate="10">
		<origin rpy="0 0 0 " xyz="0 0 0.5"/>
	</xacro:realsense_d435>	 -->

	<!-- Right Wheel Back -->
	<link name="right_wheel_back">
		<inertial>
			<mass value="${robot_wheel_mass}"/>
			<origin xyz="0 0 0" rpy="0 1.5707 1.5707"/>
			<inertia
				ixx="0.1" ixy="0.0" ixz="0.0"
				iyy="0.1" iyz="0.0"
				izz="0.1"
			/>
		</inertial>

		<visual>
			<origin xyz="0 0 0" rpy="0 1.5707 1.5707"/>
			<geometry>
				<cylinder radius="${robot_wheel_radius}" length="${robot_wheel_length}"/>
			</geometry>
		</visual>

		<collision>
			<origin xyz="0 0 0" rpy="0 1.5707 1.5707"/>
			<geometry>
				<cylinder radius="${robot_wheel_radius}" length="${robot_wheel_length}"/>
			</geometry>
		</collision>
	</link>


	<!-- Right Wheel Front-->
	<link name="right_wheel_front">
		<inertial>
			<mass value="${robot_wheel_mass}"/>
			<origin xyz="0 0 0" rpy="0 1.5707 1.5707"/>
			<inertia
				ixx="0.1" ixy="0.0" ixz="0.0"
				iyy="0.1" iyz="0.0"
				izz="0.1"
			/>
		</inertial>

		<visual>
			<origin xyz="0 0 0" rpy="0 1.5707 1.5707"/>
			<geometry>
				<cylinder radius="${robot_wheel_radius}" length="${robot_wheel_length}"/>
			</geometry>
		</visual>

		<collision>
			<origin xyz="0 0 0" rpy="0 1.5707 1.5707"/>
			<geometry>
				<cylinder radius="${robot_wheel_radius}" length="${robot_wheel_length}"/>
			</geometry>
		</collision>
	</link>



	<!-- Left wheel Back-->
	<link name="left_wheel_back">
		<inertial>
			<mass value="${robot_wheel_mass}"/>
			<origin xyz="0 0 0" rpy="0 1.5707 1.5707"/>
			<inertia
				ixx="0.1" ixy="0.0" ixz="0.0"
				iyy="0.1" iyz="0.0"
				izz="0.1"
			/>
		</inertial>

		<visual>
			<origin xyz="0 0 0" rpy="0 1.5707 1.5707"/>
			<geometry>
				<cylinder radius="${robot_wheel_radius}" length="${robot_wheel_length}"/>
			</geometry>
		</visual>

		<collision>
			<origin xyz="0 0 0" rpy="0 1.5707 1.5707"/>
			<geometry>
				<cylinder radius="${robot_wheel_radius}" length="${robot_wheel_length}"/>
			</geometry>
		</collision>
	</link>


	<!-- Left wheel Front-->
	<link name="left_wheel_front">
		<inertial>
			<mass value="${robot_wheel_mass}"/>
			<origin xyz="0 0 0" rpy="0 1.5707 1.5707"/>
			<inertia
				ixx="0.1" ixy="0.0" ixz="0.0"
				iyy="0.1" iyz="0.0"
				izz="0.1"
			/>
		</inertial>

		<visual>
			<origin xyz="0 0 0" rpy="0 1.5707 1.5707"/>
			<geometry>
				<cylinder radius="${robot_wheel_radius}" length="${robot_wheel_length}"/>
			</geometry>
		</visual>

		<collision>
			<origin xyz="0 0 0" rpy="0 1.5707 1.5707"/>
			<geometry>
				<cylinder radius="${robot_wheel_radius}" length="${robot_wheel_length}"/>
			</geometry>
		</collision>
	</link>


	<!-- Camera link for realsense -->
	<link name="camera_link">
		<inertial>
			<mass value="${camera_mass}"/>
			<origin xyz="0 0 0" rpy="0 0 0"/>
			<inertia
		        ixx="1e-6" ixy="0.0" ixz="0.0"
		        iyy="1e-6" iyz="0.0"
		        izz="1e-6"
		      />
		</inertial>

		<visual>
			<origin xyz="0 0 0" rpy="0 0 0"/>
			<geometry>
				<box size="0.05 0.05 0.05"/>
			</geometry>
		</visual>

		<collision>
			<origin xyz="0 0 0" rpy="0 0 0"/>
			<geometry>
				<box size="0.05 0.05 0.05"/>
			</geometry>
		</collision>
	</link>


	<!-- <link name="imu_link"></link> -->



	<!-- Project center to the ground -->
	<link name="robot_footprint"></link>


	<!-- Defining Joints -->

	<!-- Right Wheel Joint Back-->
	<joint type="continuous" name="right_wheel_hinge_back">
	    <origin xyz="-0.2 -0.30 0" rpy="0 0 0" />
	    <parent link="chassis"/>
	    <child link="right_wheel_back" />
	    <axis xyz="0 1 0" rpy="0 0 0" />
	    <limit effort="10000" velocity="1000" />
	    <dynamics damping="1.0" friction="1.0" />
	</joint>

	<!-- Right Wheel Joint Front-->
	<joint type="continuous" name="right_wheel_hinge_front">
	    <origin xyz="0.2 -0.30 0" rpy="0 0 0" />
	    <parent link="chassis"/>
	    <child link="right_wheel_front" />
	    <axis xyz="0 1 0" rpy="0 0 0" />
	    <limit effort="10000" velocity="1000" />
	    <dynamics damping="1.0" friction="1.0" />
	</joint>


	<!-- Left Wheel Joint Back-->
	<joint type="continuous" name="left_wheel_hinge_back">
	    <origin xyz="-0.2 0.30 0" rpy="0 0 0" />
	    <parent link="chassis"/>
	    <child link="left_wheel_back" />
	    <axis xyz="0 1 0" rpy="0 0 0" />
	    <limit effort="10000" velocity="1000" />
	    <dynamics damping="1.0" friction="1.0" />
	</joint>

	<!-- Left Wheel Joint Front-->
	<joint type="continuous" name="left_wheel_hinge_front">
	    <origin xyz="0.2 0.30 0" rpy="0 0 0" />
	    <parent link="chassis"/>
	    <child link="left_wheel_front" />
	    <axis xyz="0 1 0" rpy="0 0 0" />
	    <limit effort="10000" velocity="1000" />
	    <dynamics damping="1.0" friction="1.0" />
	</joint>

	<!-- Base Footprint Joint -->
	<joint name="robot_footprint_joint" type="fixed">
		<origin xyz="0 0 0" rpy="0 0 0" />
		<parent link="robot_footprint"/>
		<child link="chassis" />
	</joint>


	<!-- Camera Joint for realsense -->
	<joint name="camera_joint" type="fixed">
		<origin xyz="0.26 0 0" rpy="0 0 0" />
		<parent link="chassis"/>
		<child link="camera_link" />
		<axis xyz="0 1 0"/>
	</joint>

	<!-- emulating an imu sensor maybe -->
	<!-- <joint name="imu_joint" type="fixed">
		<origin xyz="0.26 0 0" rpy="0 0 0" />
		<parent link="chassis"/>
		<child link="imu_link" />
		<axis xyz="0 1 0"/>
	</joint> -->



	<!-- Color of the bot -->
	<gazebo reference="left_wheel_front">
		<material>Gazebo/Blue</material>
		<kp>1000000.0</kp> <!-- kp and kd for rubber -->
		<kd>100.0</kd>
		<mu1>1.0</mu1>
		<mu2>1.0</mu2>
		<maxVel>1.0</maxVel>
		<minDepth>0.00</minDepth>
	</gazebo>

	<gazebo reference="left_wheel_back">
		<material>Gazebo/Blue</material>
		<kp>1000000.0</kp> <!-- kp and kd for rubber -->
		<kd>100.0</kd>
		<mu1>1.0</mu1>
		<mu2>1.0</mu2>
		<maxVel>1.0</maxVel>
		<minDepth>0.00</minDepth>
	</gazebo>

	<gazebo reference="right_wheel_front">
		<material>Gazebo/Blue</material>
		<kp>1000000.0</kp> <!-- kp and kd for rubber -->
		<kd>100.0</kd>
		<mu1>1.0</mu1>
		<mu2>1.0</mu2>
		<maxVel>1.0</maxVel>
		<minDepth>0.00</minDepth>
	</gazebo>
	<gazebo reference="right_wheel_back">
		<material>Gazebo/Blue</material>
		<kp>1000000.0</kp> <!-- kp and kd for rubber -->
		<kd>100.0</kd>
		<mu1>1.0</mu1>
		<mu2>1.0</mu2>
		<maxVel>1.0</maxVel>
		<minDepth>0.00</minDepth>
	</gazebo>


	<gazebo reference="chassis">
		<material>Gazebo/Green</material>
	</gazebo>

	<xacro:include filename="$(find bob)/urdf/bob.gazebo" />

</robot>